Failure # 1 (occurred at 2023-07-14_06-06-28)
Traceback (most recent call last):
  File "/home/dh127-pc3/anaconda3/envs/flow_bibek/lib/python3.7/site-packages/ray/tune/trial_runner.py", line 426, in _process_trial
    result = self.trial_executor.fetch_result(trial)
  File "/home/dh127-pc3/anaconda3/envs/flow_bibek/lib/python3.7/site-packages/ray/tune/ray_trial_executor.py", line 378, in fetch_result
    result = ray.get(trial_future[0], DEFAULT_GET_TIMEOUT)
  File "/home/dh127-pc3/anaconda3/envs/flow_bibek/lib/python3.7/site-packages/ray/worker.py", line 1457, in get
    raise value.as_instanceof_cause()
ray.exceptions.RayTaskError(ValueError): [36mray::PPO.train()[39m (pid=2942, ip=141.225.9.193)
  File "python/ray/_raylet.pyx", line 636, in ray._raylet.execute_task
  File "python/ray/_raylet.pyx", line 619, in ray._raylet.execute_task.function_executor
  File "/home/dh127-pc3/anaconda3/envs/flow_bibek/lib/python3.7/site-packages/ray/rllib/agents/trainer.py", line 444, in train
    raise e
  File "/home/dh127-pc3/anaconda3/envs/flow_bibek/lib/python3.7/site-packages/ray/rllib/agents/trainer.py", line 433, in train
    result = Trainable.train(self)
  File "/home/dh127-pc3/anaconda3/envs/flow_bibek/lib/python3.7/site-packages/ray/tune/trainable.py", line 176, in train
    result = self._train()
  File "/home/dh127-pc3/anaconda3/envs/flow_bibek/lib/python3.7/site-packages/ray/rllib/agents/trainer_template.py", line 129, in _train
    fetches = self.optimizer.step()
  File "/home/dh127-pc3/anaconda3/envs/flow_bibek/lib/python3.7/site-packages/ray/rllib/optimizers/multi_gpu_optimizer.py", line 140, in step
    self.num_envs_per_worker, self.train_batch_size)
  File "/home/dh127-pc3/anaconda3/envs/flow_bibek/lib/python3.7/site-packages/ray/rllib/optimizers/rollout.py", line 29, in collect_samples
    next_sample = ray_get_and_free(fut_sample)
  File "/home/dh127-pc3/anaconda3/envs/flow_bibek/lib/python3.7/site-packages/ray/rllib/utils/memory.py", line 33, in ray_get_and_free
    result = ray.get(object_ids)
ray.exceptions.RayTaskError(ValueError): [36mray::RolloutWorker.sample()[39m (pid=2944, ip=141.225.9.193)
  File "python/ray/_raylet.pyx", line 636, in ray._raylet.execute_task
  File "python/ray/_raylet.pyx", line 619, in ray._raylet.execute_task.function_executor
  File "/home/dh127-pc3/anaconda3/envs/flow_bibek/lib/python3.7/site-packages/ray/rllib/evaluation/rollout_worker.py", line 471, in sample
    batches = [self.input_reader.next()]
  File "/home/dh127-pc3/anaconda3/envs/flow_bibek/lib/python3.7/site-packages/ray/rllib/evaluation/sampler.py", line 56, in next
    batches = [self.get_data()]
  File "/home/dh127-pc3/anaconda3/envs/flow_bibek/lib/python3.7/site-packages/ray/rllib/evaluation/sampler.py", line 99, in get_data
    item = next(self.rollout_provider)
  File "/home/dh127-pc3/anaconda3/envs/flow_bibek/lib/python3.7/site-packages/ray/rllib/evaluation/sampler.py", line 340, in _env_runner
    base_env.send_actions(actions_to_send)
  File "/home/dh127-pc3/anaconda3/envs/flow_bibek/lib/python3.7/site-packages/ray/rllib/env/base_env.py", line 332, in send_actions
    self.vector_env.vector_step(action_vector)
  File "/home/dh127-pc3/anaconda3/envs/flow_bibek/lib/python3.7/site-packages/ray/rllib/env/vector_env.py", line 114, in vector_step
    r, type(r)))
ValueError: Reward should be finite scalar, got nan (<class 'numpy.float64'>)

